Workbook

Sheet Vendas
A1: Data | B1: Cliente | C1: Produto | D1: Tamanho | E1: Quantidade | F1: Valor Unitário | G1: Total | H1: Custo Unitário | I1: Lucro | J1: Forma de Pagamento | K1: Status | L1: Valor Recebido | M1: Valor Pendente
A2: 46149 | B2: Nira | C2: 02167 - Legging Preto | D2: GG | E2: 1 | F2: 125 | G2: =IF(E2="","",E2*F2) -> 125 | H2: {=IFERROR(INDEX(Produtos!I:I,MATCH(C2&D2,Produtos!B:B&Produtos!C:C,0)),"")} -> 109.62 | I2: =IF(E2="","",(F2-H2)*E2) -> 15.38 | J2: Dinheiro | K2: =IF(M2<=0,"Pago","Pendente") -> Pendente | L2: 83 | M2: =IF(G2="","",G2-L2) -> 42 | Z2: =IFERROR(__xludf.DUMMYFUNCTION("IFERROR(FILTER(Config!E:E,TRIM(Config!D:D)=TRIM(C2)),"""")"),"")
B3: Nira | C3: 02167 - Legging VD Safari | D3: GG | E3: 1 | F3: 125 | G3: =IF(E3="","",E3*F3) -> 125 | H3: {=IFERROR(INDEX(Produtos!I:I,MATCH(C3&D3,Produtos!B:B&Produtos!C:C,0)),"")} -> 109.62 | I3: =IF(E3="","",(F3-H3)*E3) -> 15.38 | K3: =IF(M3<=0,"Pago","Pendente") -> Pendente | M3: =IF(G3="","",G3-L3) -> 125
B4: Silvana | C4: 02167 - Legging Preto | D4: G | E4: 1 | F4: 125 | G4: =IF(E4="","",E4*F4) -> 125 | H4: {=IFERROR(INDEX(Produtos!I:I,MATCH(C4&D4,Produtos!B:B&Produtos!C:C,0)),"")} -> 109.62 | I4: =IF(E4="","",(F4-H4)*E4) -> 15.38 | K4: =IF(M4<=0,"Pago","Pendente") -> Pendente | M4: =IF(G4="","",G4-L4) -> 125
B5: Tamy | C5: 02167 - Legging Preto | D5: M | E5: 1 | F5: 114.62 | G5: =IF(E5="","",E5*F5) -> 114.62 | H5: {=IFERROR(INDEX(Produtos!I:I,MATCH(C5&D5,Produtos!B:B&Produtos!C:C,0)),"")} -> 109.62 | I5: =IF(E5="","",(F5-H5)*E5) -> 5 | K5: =IF(M5<=0,"Pago","Pendente") -> Pendente | M5: =IF(G5="","",G5-L5) -> 114.62
B6: Tamy | C6: 02167 - Legging Preto | D6: M | E6: 1 | F6: 114.62 | G6: =IF(E6="","",E6*F6) -> 114.62 | H6: {=IFERROR(INDEX(Produtos!I:I,MATCH(C6&D6,Produtos!B:B&Produtos!C:C,0)),"")} -> 109.62 | I6: =IF(E6="","",(F6-H6)*E6) -> 5 | K6: =IF(M6<=0,"Pago","Pendente") -> Pendente | M6: =IF(G6="","",G6-L6) -> 114.62
B7: Tamy | C7: 02167 - Legging VD Safari | D7: M | E7: 1 | F7: 114.62 | G7: =IF(E7="","",E7*F7) -> 114.62 | H7: {=IFERROR(INDEX(Produtos!I:I,MATCH(C7&D7,Produtos!B:B&Produtos!C:C,0)),"")} -> 109.62 | I7: =IF(E6="","",(F6-H6)*E6) -> 5 | K7: =IF(M7<=0,"Pago","Pendente") -> Pendente | M7: =IF(G7="","",G7-L7) -> 114.62
B8: Hallana | C8: 15460 - Jaqueta Preto | D8: P | E8: 1 | F8: 322 | G8: =IF(E8="","",E8*F8) -> 322 | H8: {=IFERROR(INDEX(Produtos!I:I,MATCH(C8&D8,Produtos!B:B&Produtos!C:C,0)),"")} -> 322 | I8: =IF(E8="","",(F8-H8)*E8) -> 0 | K8: =IF(M8<=0,"Pago","Pendente") -> Pendente | M8: =IF(G8="","",G8-L8) -> 322
B9: Joziane | C9: 01387 - Pantufa Castor | D9: U | E9: 1 | F9: 125 | G9: =IF(E9="","",E9*F9) -> 125 | H9: {=IFERROR(INDEX(Produtos!I:I,MATCH(C9&D9,Produtos!B:B&Produtos!C:C,0)),"")} -> 122.77 | I9: =IF(E9="","",(F9-H9)*E9) -> 2.23 | K9: =IF(M9<=0,"Pago","Pendente") -> Pendente | M9: =IF(G9="","",G9-L9) -> 125
B10: Carol | C10: 02131-I - Legging Básica Seamless Khaki | D10: G | E10: 1 | F10: 115.9 | G10: =IF(E10="","",E10*F10) -> 115.9 | H10: {=IFERROR(INDEX(Produtos!I:I,MATCH(C10&D10,Produtos!B:B&Produtos!C:C,0)),"")} -> 86.93 | I10: =IF(E10="","",(F10-H10)*E10) -> 28.97 | K10: =IF(M10<=0,"Pago","Pendente") -> Pendente | M10: =IF(G10="","",G10-L10) -> 115.9
B11: Carol | C11: 12735 - Camiseta Branco | D11: GG | E11: 1 | F11: 127.68 | G11: =IF(E11="","",E11*F11) -> 127.68 | H11: {=IFERROR(INDEX(Produtos!I:I,MATCH(C11&D11,Produtos!B:B&Produtos!C:C,0)),"")} -> 95.76 | I11: =IF(E11="","",(F11-H11)*E11) -> 31.92 | K11: =IF(M11<=0,"Pago","Pendente") -> Pendente | M11: =IF(G11="","",G11-L11) -> 127.68
B12: Carol | C12: 20231 - Conjunto AZ Eclipse / AZ Pavão | D12: GG | E12: 1 | F12: 175 | G12: =IF(E12="","",E12*F12) -> 175 | H12: {=IFERROR(INDEX(Produtos!I:I,MATCH(C12&D12,Produtos!B:B&Produtos!C:C,0)),"")} -> 156.87 | I12: =IF(E12="","",(F12-H12)*E12) -> 18.13 | K12: =IF(M12<=0,"Pago","Pendente") -> Pendente | M12: =IF(G12="","",G12-L12) -> 175
B13: Elaine(jo) | C13: 14192 - Shorts VD Safari | D13: G | E13: 1 | F13: 95.74 | G13: =IF(E13="","",E13*F13) -> 95.74 | H13: {=IFERROR(INDEX(Produtos!I:I,MATCH(C13&D13,Produtos!B:B&Produtos!C:C,0)),"")} -> 81.81 | I13: =IF(E13="","",(F13-H13)*E13) -> 13.93 | K13: =IF(M13<=0,"Pago","Pendente") -> Pendente | M13: =IF(G13="","",G13-L13) -> 95.74
B14: Elaine(jo) | C14: 02167 - Legging Preto | D14: G | E14: 1 | F14: 125 | G14: =IF(E14="","",E14*F14) -> 125 | H14: {=IFERROR(INDEX(Produtos!I:I,MATCH(C14&D14,Produtos!B:B&Produtos!C:C,0)),"")} -> 109.62 | I14: =IF(E14="","",(F14-H14)*E14) -> 15.38 | K14: =IF(M14<=0,"Pago","Pendente") -> Pendente | M14: =IF(G14="","",G14-L14) -> 125
B15: Bruna Garcia | C15: 02181 - Legging Marsala / Vino | D15: M | E15: 1 | F15: 158.68 | G15: =IF(E15="","",E15*F15) -> 158.68 | H15: {=IFERROR(INDEX(Produtos!I:I,MATCH(C15&D15,Produtos!B:B&Produtos!C:C,0)),"")} -> 121.51 | I15: =IF(E15="","",(F15-H15)*E15) -> 37.17 | K15: =IF(M15<=0,"Pago","Pendente") -> Pendente | M15: =IF(G15="","",G15-L15) -> 158.68
B16: Regiane | C16: 20231 - Conjunto Preto / VD Líquen | D16: M | E16: 1 | F16: 175 | G16: =IF(E16="","",E16*F16) -> 175 | H16: {=IFERROR(INDEX(Produtos!I:I,MATCH(C16&D16,Produtos!B:B&Produtos!C:C,0)),"")} -> 156.87 | I16: =IF(E16="","",(F16-H16)*E16) -> 18.13 | K16: =IF(M16<=0,"Pago","Pendente") -> Pendente | M16: =IF(G16="","",G16-L16) -> 175
B17: Ivanilda | C17: 12740 - Camiseta Preto | D17: G | E17: 1 | F17: 115 | G17: =IF(E17="","",E17*F17) -> 115 | H17: {=IFERROR(INDEX(Produtos!I:I,MATCH(C17&D17,Produtos!B:B&Produtos!C:C,0)),"")} -> 87.56 | I17: =IF(E17="","",(F17-H17)*E17) -> 27.44 | K17: =IF(M17<=0,"Pago","Pendente") -> Pendente | M17: =IF(G17="","",G17-L17) -> 115
B18: Daiane Francioli | C18: 1398 - Cachecol Preto | D18: U | E18: 1 | F18: 50 | G18: =IF(E18="","",E18*F18) -> 50 | H18: {=IFERROR(INDEX(Produtos!I:I,MATCH(C18&D18,Produtos!B:B&Produtos!C:C,0)),"")} -> 43.46 | I18: =IF(E18="","",(F18-H18)*E18) -> 6.54 | K18: =IF(M18<=0,"Pago","Pendente") -> Pendente | M18: =IF(G18="","",G18-L18) -> 50
B19: Daiane Francioli | C19: 20231 - Conjunto AZ Eclipse / AZ Pavão | D19: G | E19: 1 | F19: 175 | G19: =IF(E19="","",E19*F19) -> 175 | H19: {=IFERROR(INDEX(Produtos!I:I,MATCH(C19&D19,Produtos!B:B&Produtos!C:C,0)),"")} -> 156.87 | I19: =IF(E19="","",(F19-H19)*E19) -> 18.13 | K19: =IF(M19<=0,"Pago","Pendente") -> Pendente | M19: =IF(G19="","",G19-L19) -> 175
G20: =IF(E20="","",E20*F20) | H20: {=IFERROR(INDEX(Produtos!I:I,MATCH(C20&D20,Produtos!B:B&Produtos!C:C,0)),"")} -> 0 | I20: =IF(E20="","",(F20-H20)*E20) | K20: =IF(M20<=0,"Pago","Pendente") -> Pendente | M20: =IF(G20="","",G20-L20)
G21: =IF(E21="","",E21*F21) | H21: {=IFERROR(INDEX(Produtos!I:I,MATCH(C21&D21,Produtos!B:B&Produtos!C:C,0)),"")} -> 0 | I21: =IF(E21="","",(F21-H21)*E21) | K21: =IF(M21<=0,"Pago","Pendente") -> Pendente | M21: =IF(G21="","",G21-L21)
G22: =IF(E22="","",E22*F22) | H22: {=IFERROR(INDEX(Produtos!I:I,MATCH(C22&D22,Produtos!B:B&Produtos!C:C,0)),"")} -> 0 | I22: =IF(E22="","",(F22-H22)*E22) | K22: =IF(M22<=0,"Pago","Pendente") -> Pendente | M22: =IF(G22="","",G22-L22)
G23: =IF(E23="","",E23*F23) | H23: {=IFERROR(INDEX(Produtos!I:I,MATCH(C23&D23,Produtos!B:B&Produtos!C:C,0)),"")} -> 0 | I23: =IF(E23="","",(F23-H23)*E23) | K23: =IF(M23<=0,"Pago","Pendente") -> Pendente | M23: =IF(G23="","",G23-L23)
G24: =IF(E24="","",E24*F24) | H24: {=IFERROR(INDEX(Produtos!I:I,MATCH(C24&D24,Produtos!B:B&Produtos!C:C,0)),"")} -> 0 | I24: =IF(E24="","",(F24-H24)*E24) | K24: =IF(M24<=0,"Pago","Pendente") -> Pendente | M24: =IF(G24="","",G24-L24)
G25: =IF(E25="","",E25*F25) | H25: {=IFERROR(INDEX(Produtos!I:I,MATCH(C25&D25,Produtos!B:B&Produtos!C:C,0)),"")} -> 0 | I25: =IF(E25="","",(F25-H25)*E25) | K25: =IF(M25<=0,"Pago","Pendente") -> Pendente | M25: =IF(G25="","",G25-L25)
G26: =IF(E26="","",E26*F26) | H26: {=IFERROR(INDEX(Produtos!I:I,MATCH(C26&D26,Produtos!B:B&Produtos!C:C,0)),"")} -> 0 | I26: =IF(E26="","",(F26-H26)*E26) | K26: =IF(M26<=0,"Pago","Pendente") -> Pendente | M26: =IF(G26="","",G26-L26)
G27: =IF(E27="","",E27*F27) | H27: {=IFERROR(INDEX(Produtos!I:I,MATCH(C27&D27,Produtos!B:B&Produtos!C:C,0)),"")} -> 0 | I27: =IF(E27="","",(F27-H27)*E27) | K27: =IF(M27<=0,"Pago","Pendente") -> Pendente | M27: =IF(G27="","",G27-L27)
G28: =IF(E28="","",E28*F28) | H28: {=IFERROR(INDEX(Produtos!I:I,MATCH(C28&D28,Produtos!B:B&Produtos!C:C,0)),"")} -> 0 | I28: =IF(E28="","",(F28-H28)*E28) | K28: =IF(M28<=0,"Pago","Pendente") -> Pendente | M28: =IF(G28="","",G28-L28)
G29: =IF(E29="","",E29*F29) | H29: {=IFERROR(INDEX(Produtos!I:I,MATCH(C29&D29,Produtos!B:B&Produtos!C:C,0)),"")} -> 0 | I29: =IF(E29="","",(F29-H29)*E29) | K29: =IF(M29<=0,"Pago","Pendente") -> Pendente | M29: =IF(G29="","",G29-L29)
G30: =IF(E30="","",E30*F30) | H30: {=IFERROR(INDEX(Produtos!I:I,MATCH(C30&D30,Produtos!B:B&Produtos!C:C,0)),"")} -> 0 | I30: =IF(E30="","",(F30-H30)*E30) | K30: =IF(M30<=0,"Pago","Pendente") -> Pendente | M30: =IF(G30="","",G30-L30)
G31: =IF(E31="","",E31*F31) | H31: {=IFERROR(INDEX(Produtos!I:I,MATCH(C31&D31,Produtos!B:B&Produtos!C:C,0)),"")} -> 0 | I31: =IF(E31="","",(F31-H31)*E31) | K31: =IF(M31<=0,"Pago","Pendente") -> Pendente | M31: =IF(G31="","",G31-L31)
... G401: =IF(E401="","",E401*F401) | H401: {=IFERROR(INDEX(Produtos!I:I,MATCH(C401&D401,Produtos!B:B&Produtos!C:C,0)),"")} -> 0 | I401: =IF(E401="","",(F401-H401)*E401) | K401: =IF(M401<=0,"Pago","Pendente") -> Pendente | M401: =IF(G401="","",G401-L401)

Sheet Clientes
A1: Código | B1: Nome | C1: Telefone | D1: Cidade | E1: Intagram | F1: Data Cadastro | G1: Ultima compra | H1: Total comprado | I1: Quantidade | J1: Ticket Médio | K1: Observações
A2: ="C"&TEXT(ROW(A2),"000") -> C002 | B2: Cliente Avulso | F2: 46149 | G2: =IFERROR(MAX(FILTRAR(Vendas!A:A,Vendas!B:B=B2)),"") | H2: =IF(B2="","",SUMIF(Vendas!B:B,B2,Vendas!G:G)) -> 0 | I2: =IF(B2="","",COUNTIF(Vendas!B:B,B2)) -> 0 | J2: =IFERROR(H2/I2,0) -> 0
A3: ="C"&TEXT(ROW(A3),"000") -> C003 | B3: Silvana | D3: Sertanópolis | F3: 46150 | G3: =IFERROR(MAX(FILTRAR(Vendas!A:A,Vendas!B:B=B3)),"") | H3: =IF(B3="","",SUMIF(Vendas!B:B,B3,Vendas!G:G)) -> 125 | I3: =IF(B3="","",COUNTIF(Vendas!B:B,B3)) -> 1 | J3: =IFERROR(H3/I3,0) -> 125
A4: ="C"&TEXT(ROW(A4),"000") -> C004 | B4: Nira | D4: Sertanópolis | F4: 46151 | G4: =IFERROR(MAX(FILTRAR(Vendas!A:A,Vendas!B:B=B4)),"") | H4: =IF(B4="","",SUMIF(Vendas!B:B,B4,Vendas!G:G)) -> 250 | I4: =IF(B4="","",COUNTIF(Vendas!B:B,B4)) -> 2 | J4: =IFERROR(H4/I4,0) -> 125
A5: ="C"&TEXT(ROW(A5),"000") -> C005 | B5: Daiane Francioli | D5: Sertanópolis | F5: 46152 | G5: =IFERROR(MAX(FILTRAR(Vendas!A:A,Vendas!B:B=B5)),"") | H5: =IF(B5="","",SUMIF(Vendas!B:B,B5,Vendas!G:G)) -> 225 | I5: =IF(B5="","",COUNTIF(Vendas!B:B,B5)) -> 2 | J5: =IFERROR(H5/I5,0) -> 112.5
A6: ="C"&TEXT(ROW(A6),"000") -> C006 | B6: Carol | D6: Sertanópolis | F6: 46153 | G6: =IFERROR(MAX(FILTRAR(Vendas!A:A,Vendas!B:B=B6)),"") | H6: =IF(B6="","",SUMIF(Vendas!B:B,B6,Vendas!G:G)) -> 418.58 | I6: =IF(B6="","",COUNTIF(Vendas!B:B,B6)) -> 3 | J6: =IFERROR(H6/I6,0) -> 139.52667
A7: ="C"&TEXT(ROW(A7),"000") -> C007 | B7: Joziane | D7: Sertanópolis | F7: 46154 | G7: =IFERROR(MAX(FILTRAR(Vendas!A:A,Vendas!B:B=B7)),"") | H7: =IF(B7="","",SUMIF(Vendas!B:B,B7,Vendas!G:G)) -> 125 | I7: =IF(B7="","",COUNTIF(Vendas!B:B,B7)) -> 1 | J7: =IFERROR(H7/I7,0) -> 125
A8: ="C"&TEXT(ROW(A8),"000") -> C008 | B8: Elaine(jo) | D8: Sertanópolis | F8: 46155 | G8: =IFERROR(MAX(FILTRAR(Vendas!A:A,Vendas!B:B=B8)),"") | H8: =IF(B8="","",SUMIF(Vendas!B:B,B8,Vendas!G:G)) -> 220.74 | I8: =IF(B8="","",COUNTIF(Vendas!B:B,B8)) -> 2 | J8: =IFERROR(H8/I8,0) -> 110.37
A9: ="C"&TEXT(ROW(A9),"000") -> C009 | B9: Bruna Garcia | D9: Sertanópolis | F9: 46156 | G9: =IFERROR(MAX(FILTRAR(Vendas!A:A,Vendas!B:B=B9)),"") | H9: =IF(B9="","",SUMIF(Vendas!B:B,B9,Vendas!G:G)) -> 158.68 | I9: =IF(B9="","",COUNTIF(Vendas!B:B,B9)) -> 1 | J9: =IFERROR(H9/I9,0) -> 158.68
A10: ="C"&TEXT(ROW(A10),"000") -> C010 | B10: Regiane | D10: Sertanópolis | F10: 46157 | G10: =IFERROR(MAX(FILTRAR(Vendas!A:A,Vendas!B:B=B10)),"") | H10: =IF(B10="","",SUMIF(Vendas!B:B,B10,Vendas!G:G)) -> 175 | I10: =IF(B10="","",COUNTIF(Vendas!B:B,B10)) -> 1 | J10: =IFERROR(H10/I10,0) -> 175
A11: ="C"&TEXT(ROW(A11),"000") -> C011 | B11: Ivanilda | D11: Sertanópolis | F11: 46158 | G11: =IFERROR(MAX(FILTRAR(Vendas!A:A,Vendas!B:B=B11)),"") | H11: =IF(B11="","",SUMIF(Vendas!B:B,B11,Vendas!G:G)) -> 115 | I11: =IF(B11="","",COUNTIF(Vendas!B:B,B11)) -> 1 | J11: =IFERROR(H11/I11,0) -> 115
A12: ="C"&TEXT(ROW(A12),"000") -> C012 | B12: Edilaine | D12: Sertanópolis | F12: 46159 | G12: =IFERROR(MAX(FILTRAR(Vendas!A:A,Vendas!B:B=B12)),"") | H12: =IF(B12="","",SUMIF(Vendas!B:B,B12,Vendas!G:G)) -> 0 | I12: =IF(B12="","",COUNTIF(Vendas!B:B,B12)) -> 0 | J12: =IFERROR(H12/I12,0) -> 0
A13: ="C"&TEXT(ROW(A13),"000") -> C013 | B13: Odete | D13: Sertanópolis | F13: 46160 | G13: =IFERROR(MAX(FILTRAR(Vendas!A:A,Vendas!B:B=B13)),"") | H13: =IF(B13="","",SUMIF(Vendas!B:B,B13,Vendas!G:G)) -> 0 | I13: =IF(B13="","",COUNTIF(Vendas!B:B,B13)) -> 0 | J13: =IFERROR(H13/I13,0) -> 0
A14: ="C"&TEXT(ROW(A14),"000") -> C014 | B14: Kerowlen | D14: Sertanópolis | F14: 46161 | G14: =IFERROR(MAX(FILTRAR(Vendas!A:A,Vendas!B:B=B14)),"") | H14: =IF(B14="","",SUMIF(Vendas!B:B,B14,Vendas!G:G)) -> 0 | I14: =IF(B14="","",COUNTIF(Vendas!B:B,B14)) -> 0 | J14: =IFERROR(H14/I14,0) -> 0
... A26: ="C"&TEXT(ROW(A26),"000") -> C026 | B26: Eliana Rodrigues | D26: Sertanópolis | F26: 46173 | G26: =IFERROR(MAX(FILTRAR(Vendas!A:A,Vendas!B:B=B26)),"") | H26: =IF(B26="","",SUMIF(Vendas!B:B,B26,Vendas!G:G)) -> 0 | I26: =IF(B26="","",COUNTIF(Vendas!B:B,B26)) -> 0 | J26: =IFERROR(H26/I26,0) -> 0
A27: ="C"&TEXT(ROW(A27),"000") -> C027 | G27: =IFERROR(MAX(FILTRAR(Vendas!A:A,Vendas!B:B=B27)),"") | H27: =IF(B27="","",SUMIF(Vendas!B:B,B27,Vendas!G:G)) | I27: =IF(B27="","",COUNTIF(Vendas!B:B,B27)) | J27: =IFERROR(H27/I27,0) -> 0
A28: ="C"&TEXT(ROW(A28),"000") -> C028 | G28: =IFERROR(MAX(FILTRAR(Vendas!A:A,Vendas!B:B=B28)),"") | H28: =IF(B28="","",SUMIF(Vendas!B:B,B28,Vendas!G:G)) | I28: =IF(B28="","",COUNTIF(Vendas!B:B,B28)) | J28: =IFERROR(H28/I28,0) -> 0
A29: ="C"&TEXT(ROW(A29),"000") -> C029 | G29: =IFERROR(MAX(FILTRAR(Vendas!A:A,Vendas!B:B=B29)),"") | H29: =IF(B29="","",SUMIF(Vendas!B:B,B29,Vendas!G:G)) | I29: =IF(B29="","",COUNTIF(Vendas!B:B,B29)) | J29: =IFERROR(H29/I29,0) -> 0
A30: ="C"&TEXT(ROW(A30),"000") -> C030 | G30: =IFERROR(MAX(FILTRAR(Vendas!A:A,Vendas!B:B=B30)),"") | H30: =IF(B30="","",SUMIF(Vendas!B:B,B30,Vendas!G:G)) | I30: =IF(B30="","",COUNTIF(Vendas!B:B,B30)) | J30: =IFERROR(H30/I30,0) -> 0
A31: ="C"&TEXT(ROW(A31),"000") -> C031 | G31: =IFERROR(MAX(FILTRAR(Vendas!A:A,Vendas!B:B=B31)),"") | H31: =IF(B31="","",SUMIF(Vendas!B:B,B31,Vendas!G:G)) | I31: =IF(B31="","",COUNTIF(Vendas!B:B,B31)) | J31: =IFERROR(H31/I31,0) -> 0
A32: ="C"&TEXT(ROW(A32),"000") -> C032 | G32: =IFERROR(MAX(FILTRAR(Vendas!A:A,Vendas!B:B=B32)),"") | H32: =IF(B32="","",SUMIF(Vendas!B:B,B32,Vendas!G:G)) | I32: =IF(B32="","",COUNTIF(Vendas!B:B,B32)) | J32: =IFERROR(H32/I32,0) -> 0
A33: ="C"&TEXT(ROW(A33),"000") -> C033 | G33: =IFERROR(MAX(FILTRAR(Vendas!A:A,Vendas!B:B=B33)),"") | H33: =IF(B33="","",SUMIF(Vendas!B:B,B33,Vendas!G:G)) | I33: =IF(B33="","",COUNTIF(Vendas!B:B,B33)) | J33: =IFERROR(H33/I33,0) -> 0
A34: ="C"&TEXT(ROW(A34),"000") -> C034 | G34: =IFERROR(MAX(FILTRAR(Vendas!A:A,Vendas!B:B=B34)),"") | H34: =IF(B34="","",SUMIF(Vendas!B:B,B34,Vendas!G:G)) | I34: =IF(B34="","",COUNTIF(Vendas!B:B,B34)) | J34: =IFERROR(H34/I34,0) -> 0
A35: ="C"&TEXT(ROW(A35),"000") -> C035 | G35: =IFERROR(MAX(FILTRAR(Vendas!A:A,Vendas!B:B=B35)),"") | H35: =IF(B35="","",SUMIF(Vendas!B:B,B35,Vendas!G:G)) | I35: =IF(B35="","",COUNTIF(Vendas!B:B,B35)) | J35: =IFERROR(H35/I35,0) -> 0
A36: ="C"&TEXT(ROW(A36),"000") -> C036 | G36: =IFERROR(MAX(FILTRAR(Vendas!A:A,Vendas!B:B=B36)),"") | H36: =IF(B36="","",SUMIF(Vendas!B:B,B36,Vendas!G:G)) | I36: =IF(B36="","",COUNTIF(Vendas!B:B,B36)) | J36: =IFERROR(H36/I36,0) -> 0
A37: ="C"&TEXT(ROW(A37),"000") -> C037 | G37: =IFERROR(MAX(FILTRAR(Vendas!A:A,Vendas!B:B=B37)),"") | H37: =IF(B37="","",SUMIF(Vendas!B:B,B37,Vendas!G:G)) | I37: =IF(B37="","",COUNTIF(Vendas!B:B,B37)) | J37: =IFERROR(H37/I37,0) -> 0
A38: ="C"&TEXT(ROW(A38),"000") -> C038 | G38: =IFERROR(MAX(FILTRAR(Vendas!A:A,Vendas!B:B=B38)),"") | H38: =IF(B38="","",SUMIF(Vendas!B:B,B38,Vendas!G:G)) | I38: =IF(B38="","",COUNTIF(Vendas!B:B,B38)) | J38: =IFERROR(H38/I38,0) -> 0
... A399: ="C"&TEXT(ROW(A399),"000") -> C399 | G399: =IFERROR(MAX(FILTRAR(Vendas!A:A,Vendas!B:B=B399)),"") | H399: =IF(B399="","",SUMIF(Vendas!B:B,B399,Vendas!G:G)) | I399: =IF(B399="","",COUNTIF(Vendas!B:B,B399)) | J399: =IFERROR(H399/I399,0) -> 0
A400: ="C"&TEXT(ROW(A400),"000") -> C400 | G400: =IFERROR(MAX(FILTRAR(Vendas!A:A,Vendas!B:B=B400)),"") | H400: =IF(B400="","",SUMIF(Vendas!B:B,B400,Vendas!G:G)) | I400: =IF(B400="","",COUNTIF(Vendas!B:B,B400))

Sheet Produtos
A1: Código | B1: Produto | C1: Tamanho | D1: Categoria | E1: Custo | F1: Frete | G1: IPI | H1: Embalagem | I1: Custo Total | J1: Margem % | K1: Preço sugerido | L1: Preço minimo | M1: Taxa 3x | N1: 3x sem juros | O1: Taxa 12x | P1: 12x sem juros | Q1: Estoque Atual
A2: ="P" & TEXT(ROW(A2),"000") -> P002 | B2: 1398 - Cachecol Preto | C2: U | D2: Dicorpo | E2: 43.46 | H2: =IF(OR(D2="Perfume",D2="Via Aroma"),5,"") | I2: =SUM(E2:H2) -> 43.46 | J2: =IF(D2="","",IF(D2="Perfume",1,IF(D2="Via Aroma",0.6,IF(D2="Dicorpo",0.8,"")))) -> 0.8 | K2: =IF(I2="","",I2*(1+J2)) -> 78.228 | L2: =IF(I2="","",I2*1.3) -> 56.498 | M2: =0.0612 -> 0.0612 | N2: =IF(K2="","",K2/(1-M2)) -> 83.327652 | O2: =0.124 -> 0.124 | P2: =IF(K2="","",K2/(1-O2)) -> 89.30137 | Q2: =SUMIFS(Entradas!D:D,Entradas!B:B,B2,Entradas!C:C,C2) - SUMIFS(Vendas!E:E,Vendas!C:C,B2,Vendas!D:D,C2) -> 0
A3: ="P" & TEXT(ROW(A3),"000") -> P003 | B3: 02131-I - Legging Básica Seamless Khaki | C3: G | D3: Dicorpo | E3: 86.93 | H3: =IF(OR(D3="Perfume",D3="Via Aroma"),5,"") | I3: =SUM(E3:H3) -> 86.93 | J3: =IF(D3="","",IF(D3="Perfume",1,IF(D3="Via Aroma",0.6,IF(D3="Dicorpo",0.8,"")))) -> 0.8 | K3: =IF(I3="","",I3*(1+J3)) -> 156.474 | L3: =IF(I3="","",I3*1.3) -> 113.009 | M3: =0.0612 -> 0.0612 | N3: =IF(K3="","",K3/(1-M3)) -> 166.67448 | O3: =0.124 -> 0.124 | P3: =IF(K3="","",K3/(1-O3)) -> 178.62329 | Q3: =SUMIFS(Entradas!D:D,Entradas!B:B,B3,Entradas!C:C,C3) - SUMIFS(Vendas!E:E,Vendas!C:C,B3,Vendas!D:D,C3) -> 0
A4: ="P" & TEXT(ROW(A4),"000") -> P004 | B4: 02167 - Legging Preto | C4: M | D4: Dicorpo | E4: 109.62 | H4: =IF(OR(D4="Perfume",D4="Via Aroma"),5,"") | I4: =SUM(E4:H4) -> 109.62 | J4: =IF(D4="","",IF(D4="Perfume",1,IF(D4="Via Aroma",0.6,IF(D4="Dicorpo",0.8,"")))) -> 0.8 | K4: =IF(I4="","",I4*(1+J4)) -> 197.316 | L4: =IF(I4="","",I4*1.3) -> 142.506 | M4: =0.0612 -> 0.0612 | N4: =IF(K4="","",K4/(1-M4)) -> 210.17895 | O4: =0.124 -> 0.124 | P4: =IF(K4="","",K4/(1-O4)) -> 225.24658 | Q4: =SUMIFS(Entradas!D:D,Entradas!B:B,B4,Entradas!C:C,C4) - SUMIFS(Vendas!E:E,Vendas!C:C,B4,Vendas!D:D,C4) -> 0
A5: ="P" & TEXT(ROW(A5),"000") -> P005 | B5: 02167 - Legging Preto | C5: G | D5: Dicorpo | E5: 109.62 | H5: =IF(OR(D5="Perfume",D5="Via Aroma"),5,"") | I5: =SUM(E5:H5) -> 109.62 | J5: =IF(D5="","",IF(D5="Perfume",1,IF(D5="Via Aroma",0.6,IF(D5="Dicorpo",0.8,"")))) -> 0.8 | K5: =IF(I5="","",I5*(1+J5)) -> 197.316 | L5: =IF(I5="","",I5*1.3) -> 142.506 | M5: =0.0612 -> 0.0612 | N5: =IF(K5="","",K5/(1-M5)) -> 210.17895 | O5: =0.124 -> 0.124 | P5: =IF(K5="","",K5/(1-O5)) -> 225.24658 | Q5: =SUMIFS(Entradas!D:D,Entradas!B:B,B5,Entradas!C:C,C5) - SUMIFS(Vendas!E:E,Vendas!C:C,B5,Vendas!D:D,C5) -> 0
A6: ="P" & TEXT(ROW(A6),"000") -> P006 | B6: 02167 - Legging Preto | C6: GG | D6: Dicorpo | E6: 109.62 | H6: =IF(OR(D6="Perfume",D6="Via Aroma"),5,"") | I6: =SUM(E6:H6) -> 109.62 | J6: =IF(D6="","",IF(D6="Perfume",1,IF(D6="Via Aroma",0.6,IF(D6="Dicorpo",0.8,"")))) -> 0.8 | K6: =IF(I6="","",I6*(1+J6)) -> 197.316 | L6: =IF(I6="","",I6*1.3) -> 142.506 | M6: =0.0612 -> 0.0612 | N6: =IF(K6="","",K6/(1-M6)) -> 210.17895 | O6: =0.124 -> 0.124 | P6: =IF(K6="","",K6/(1-O6)) -> 225.24658 | Q6: =SUMIFS(Entradas!D:D,Entradas!B:B,B6,Entradas!C:C,C6) - SUMIFS(Vendas!E:E,Vendas!C:C,B6,Vendas!D:D,C6) -> 0
A7: ="P" & TEXT(ROW(A7),"000") -> P007 | B7: 02167 - Legging VD Safari | C7: M | D7: Dicorpo | E7: 109.62 | H7: =IF(OR(D7="Perfume",D7="Via Aroma"),5,"") | I7: =SUM(E7:H7) -> 109.62 | J7: =IF(D7="","",IF(D7="Perfume",1,IF(D7="Via Aroma",0.6,IF(D7="Dicorpo",0.8,"")))) -> 0.8 | K7: =IF(I7="","",I7*(1+J7)) -> 197.316 | L7: =IF(I7="","",I7*1.3) -> 142.506 | M7: =0.0612 -> 0.0612 | N7: =IF(K7="","",K7/(1-M7)) -> 210.17895 | O7: =0.124 -> 0.124 | P7: =IF(K7="","",K7/(1-O7)) -> 225.24658 | Q7: =SUMIFS(Entradas!D:D,Entradas!B:B,B7,Entradas!C:C,C7) - SUMIFS(Vendas!E:E,Vendas!C:C,B7,Vendas!D:D,C7) -> 0
A8: ="P" & TEXT(ROW(A8),"000") -> P008 | B8: 02167 - Legging VD Safari | C8: GG | D8: Dicorpo | E8: 109.62 | H8: =IF(OR(D8="Perfume",D8="Via Aroma"),5,"") | I8: =SUM(E8:H8) -> 109.62 | J8: =IF(D8="","",IF(D8="Perfume",1,IF(D8="Via Aroma",0.6,IF(D8="Dicorpo",0.8,"")))) -> 0.8 | K8: =IF(I8="","",I8*(1+J8)) -> 197.316 | L8: =IF(I8="","",I8*1.3) -> 142.506 | M8: =0.0612 -> 0.0612 | N8: =IF(K8="","",K8/(1-M8)) -> 210.17895 | O8: =0.124 -> 0.124 | P8: =IF(K8="","",K8/(1-O8)) -> 225.24658 | Q8: =SUMIFS(Entradas!D:D,Entradas!B:B,B8,Entradas!C:C,C8) - SUMIFS(Vendas!E:E,Vendas!C:C,B8,Vendas!D:D,C8) -> 0
A9: ="P" & TEXT(ROW(A9),"000") -> P009 | B9: 02169 - Pescador Preto | C9: M | D9: Dicorpo | E9: 93.23 | H9: =IF(OR(D9="Perfume",D9="Via Aroma"),5,"") | I9: =SUM(E9:H9) -> 93.23 | J9: =IF(D9="","",IF(D9="Perfume",1,IF(D9="Via Aroma",0.6,IF(D9="Dicorpo",0.8,"")))) -> 0.8 | K9: =IF(I9="","",I9*(1+J9)) -> 167.814 | L9: =IF(I9="","",I9*1.3) -> 121.199 | M9: =0.0612 -> 0.0612 | N9: =IF(K9="","",K9/(1-M9)) -> 178.75373 | O9: =0.124 -> 0.124 | P9: =IF(K9="","",K9/(1-O9)) -> 191.56849 | Q9: =SUMIFS(Entradas!D:D,Entradas!B:B,B9,Entradas!C:C,C9) - SUMIFS(Vendas!E:E,Vendas!C:C,B9,Vendas!D:D,C9) -> 1
A10: ="P" & TEXT(ROW(A10),"000") -> P010 | B10: 12735 - Camiseta Branco | C10: GG | D10: Dicorpo | E10: 95.76 | H10: =IF(OR(D10="Perfume",D10="Via Aroma"),5,"") | I10: =SUM(E10:H10) -> 95.76 | J10: =IF(D10="","",IF(D10="Perfume",1,IF(D10="Via Aroma",0.6,IF(D10="Dicorpo",0.8,"")))) -> 0.8 | K10: =IF(I10="","",I10*(1+J10)) -> 172.368 | L10: =IF(I10="","",I10*1.3) -> 124.488 | M10: =0.0612 -> 0.0612 | N10: =IF(K10="","",K10/(1-M10)) -> 183.6046 | O10: =0.124 -> 0.124 | P10: =IF(K10="","",K10/(1-O10)) -> 196.76712 | Q10: =SUMIFS(Entradas!D:D,Entradas!B:B,B10,Entradas!C:C,C10) - SUMIFS(Vendas!E:E,Vendas!C:C,B10,Vendas!D:D,C10) -> 0
A11: ="P" & TEXT(ROW(A11),"000") -> P011 | B11: 12740 - Camiseta Preto | C11: G | D11: Dicorpo | E11: 87.56 | H11: =IF(OR(D11="Perfume",D11="Via Aroma"),5,"") | I11: =SUM(E11:H11) -> 87.56 | J11: =IF(D11="","",IF(D11="Perfume",1,IF(D11="Via Aroma",0.6,IF(D11="Dicorpo",0.8,"")))) -> 0.8 | K11: =IF(I11="","",I11*(1+J11)) -> 157.608 | L11: =IF(I11="","",I11*1.3) -> 113.828 | M11: =0.0612 -> 0.0612 | N11: =IF(K11="","",K11/(1-M11)) -> 167.8824 | O11: =0.124 -> 0.124 | P11: =IF(K11="","",K11/(1-O11)) -> 179.91781 | Q11: =SUMIFS(Entradas!D:D,Entradas!B:B,B11,Entradas!C:C,C11) - SUMIFS(Vendas!E:E,Vendas!C:C,B11,Vendas!D:D,C11) -> 0
A12: ="P" & TEXT(ROW(A12),"000") -> P012 | B12: 20231 - Conjunto Preto / VD Líquen | C12: M | D12: Dicorpo | E12: 156.87 | H12: =IF(OR(D12="Perfume",D12="Via Aroma"),5,"") | I12: =SUM(E12:H12) -> 156.87 | J12: =IF(D12="","",IF(D12="Perfume",1,IF(D12="Via Aroma",0.6,IF(D12="Dicorpo",0.8,"")))) -> 0.8 | K12: =IF(I12="","",I12*(1+J12)) -> 282.366 | L12: =IF(I12="","",I12*1.3) -> 203.931 | M12: =0.0612 -> 0.0612 | N12: =IF(K12="","",K12/(1-M12)) -> 300.77333 | O12: =0.124 -> 0.124 | P12: =IF(K12="","",K12/(1-O12)) -> 322.33562 | Q12: =SUMIFS(Entradas!D:D,Entradas!B:B,B12,Entradas!C:C,C12) - SUMIFS(Vendas!E:E,Vendas!C:C,B12,Vendas!D:D,C12) -> 0
A13: ="P" & TEXT(ROW(A13),"000") -> P013 | B13: 20231 - Conjunto AZ Eclipse / AZ Pavão | C13: GG | D13: Dicorpo | E13: 156.87 | H13: =IF(OR(D13="Perfume",D13="Via Aroma"),5,"") | I13: =SUM(E13:H13) -> 156.87 | J13: =IF(D13="","",IF(D13="Perfume",1,IF(D13="Via Aroma",0.6,IF(D13="Dicorpo",0.8,"")))) -> 0.8 | K13: =IF(I13="","",I13*(1+J13)) -> 282.366 | L13: =IF(I13="","",I13*1.3) -> 203.931 | M13: =0.0612 -> 0.0612 | N13: =IF(K13="","",K13/(1-M13)) -> 300.77333 | O13: =0.124 -> 0.124 | P13: =IF(K13="","",K13/(1-O13)) -> 322.33562 | Q13: =SUMIFS(Entradas!D:D,Entradas!B:B,B13,Entradas!C:C,C13) - SUMIFS(Vendas!E:E,Vendas!C:C,B13,Vendas!D:D,C13) -> 0
A14: ="P" & TEXT(ROW(A14),"000") -> P014 | B14: 20231 - Conjunto AZ Eclipse / AZ Pavão | C14: G | D14: Dicorpo | E14: 156.87 | H14: =IF(OR(D14="Perfume",D14="Via Aroma"),5,"") | I14: =SUM(E14:H14) -> 156.87 | J14: =IF(D14="","",IF(D14="Perfume",1,IF(D14="Via Aroma",0.6,IF(D14="Dicorpo",0.8,"")))) -> 0.8 | K14: =IF(I14="","",I14*(1+J14)) -> 282.366 | L14: =IF(I14="","",I14*1.3) -> 203.931 | M14: =0.0612 -> 0.0612 | N14: =IF(K14="","",K14/(1-M14)) -> 300.77333 | O14: =0.124 -> 0.124 | P14: =IF(K14="","",K14/(1-O14)) -> 322.33562 | Q14: =SUMIFS(Entradas!D:D,Entradas!B:B,B14,Entradas!C:C,C14) - SUMIFS(Vendas!E:E,Vendas!C:C,B14,Vendas!D:D,C14) -> 0
A15: ="P" & TEXT(ROW(A15),"000") -> P015 | B15: 01387 - Pantufa Castor | C15: U | D15: Dicorpo | E15: 112.77 | F15: 10 | H15: =IF(OR(D15="Perfume",D15="Via Aroma"),5,"") | I15: =SUM(E15:H15) -> 122.77 | J15: =IF(D15="","",IF(D15="Perfume",1,IF(D15="Via Aroma",0.6,IF(D15="Dicorpo",0.8,"")))) -> 0.8 | K15: =IF(I15="","",I15*(1+J15)) -> 220.986 | L15: =IF(I15="","",I15*1.3) -> 159.601 | M15: =0.0612 -> 0.0612 | N15: =IF(K15="","",K15/(1-M15)) -> 235.39199 | O15: =0.124 -> 0.124 | P15: =IF(K15="","",K15/(1-O15)) -> 252.26712 | Q15: =SUMIFS(Entradas!D:D,Entradas!B:B,B15,Entradas!C:C,C15) - SUMIFS(Vendas!E:E,Vendas!C:C,B15,Vendas!D:D,C15) -> 0
A16: ="P" & TEXT(ROW(A16),"000") -> P016 | B16: 02181 - Legging Marsala / Vino | C16: M | D16: Dicorpo | E16: 111.51 | F16: 10 | H16: =IF(OR(D16="Perfume",D16="Via Aroma"),5,"") | I16: =SUM(E16:H16) -> 121.51 | J16: =IF(D16="","",IF(D16="Perfume",1,IF(D16="Via Aroma",0.6,IF(D16="Dicorpo",0.8,"")))) -> 0.8 | K16: =IF(I16="","",I16*(1+J16)) -> 218.718 | L16: =IF(I16="","",I16*1.3) -> 157.963 | M16: =0.0612 -> 0.0612 | N16: =IF(K16="","",K16/(1-M16)) -> 232.97614 | O16: =0.124 -> 0.124 | P16: =IF(K16="","",K16/(1-O16)) -> 249.67808 | Q16: =SUMIFS(Entradas!D:D,Entradas!B:B,B16,Entradas!C:C,C16) - SUMIFS(Vendas!E:E,Vendas!C:C,B16,Vendas!D:D,C16) -> 0
A17: ="P" & TEXT(ROW(A17),"000") -> P017 | B17: 14192 - Shorts VD Safari | C17: G | D17: Dicorpo | E17: 71.81 | F17: 10 | H17: =IF(OR(D17="Perfume",D17="Via Aroma"),5,"") | I17: =SUM(E17:H17) -> 81.81 | J17: =IF(D17="","",IF(D17="Perfume",1,IF(D17="Via Aroma",0.6,IF(D17="Dicorpo",0.8,"")))) -> 0.8 | K17: =IF(I17="","",I17*(1+J17)) -> 147.258 | L17: =IF(I17="","",I17*1.3) -> 106.353 | M17: =0.0612 -> 0.0612 | N17: =IF(K17="","",K17/(1-M17)) -> 156.85769 | O17: =0.124 -> 0.124 | P17: =IF(K17="","",K17/(1-O17)) -> 168.10274 | Q17: =SUMIFS(Entradas!D:D,Entradas!B:B,B17,Entradas!C:C,C17) - SUMIFS(Vendas!E:E,Vendas!C:C,B17,Vendas!D:D,C17) -> 0
A18: ="P" & TEXT(ROW(A18),"000") -> P018 | B18: 15460 - Jaqueta Preto | C18: P | D18: Dicorpo | E18: 322 | H18: =IF(OR(D18="Perfume",D18="Via Aroma"),5,"") | I18: =SUM(E18:H18) -> 322 | J18: =IF(D18="","",IF(D18="Perfume",1,IF(D18="Via Aroma",0.6,IF(D18="Dicorpo",0.8,"")))) -> 0.8 | K18: =IF(I18="","",I18*(1+J18)) -> 579.6 | L18: =IF(I18="","",I18*1.3) -> 418.6 | M18: =0.0612 -> 0.0612 | N18: =IF(K18="","",K18/(1-M18)) -> 617.38389 | O18: =0.124 -> 0.124 | P18: =IF(K18="","",K18/(1-O18)) -> 661.64384 | Q18: =SUMIFS(Entradas!D:D,Entradas!B:B,B18,Entradas!C:C,C18) - SUMIFS(Vendas!E:E,Vendas!C:C,B18,Vendas!D:D,C18) -> 0
A19: ="P" & TEXT(ROW(A19),"000") -> P019 | B19: AGUA PERF. CASZULO 500ML BAMBU ORIENTAL | D19: Via Aroma | E19: 12.5 | F19: 1.2 | G19: 2.3 | H19: =IF(OR(D19="Perfume",D19="Via Aroma"),5,"") -> 5 | I19: =SUM(E19:H19) -> 21 | J19: =IF(D19="","",IF(D19="Perfume",1,IF(D19="Via Aroma",0.6,IF(D19="Dicorpo",0.8,"")))) -> 0.6 | K19: =IF(I19="","",I19*(1+J19)) -> 33.6 | L19: =IF(I19="","",I19*1.3) -> 27.3 | M19: =0.0612 -> 0.0612 | N19: =IF(K19="","",K19/(1-M19)) -> 35.790371 | O19: =0.124 -> 0.124 | P19: =IF(K19="","",K19/(1-O19)) -> 38.356164 | Q19: =SUMIFS(Entradas!D:D,Entradas!B:B,B19,Entradas!C:C,C19) - SUMIFS(Vendas!E:E,Vendas!C:C,B19,Vendas!D:D,C19) -> 0
A20: ="P" & TEXT(ROW(A20),"000") -> P020 | B20: AGUA PERF. CASZULO 500ML CAPIM LIMAO | D20: Via Aroma | E20: 12.5 | F20: 1.2 | G20: 2.3 | H20: =IF(OR(D20="Perfume",D20="Via Aroma"),5,"") -> 5 | I20: =SUM(E20:H20) -> 21 | J20: =IF(D20="","",IF(D20="Perfume",1,IF(D20="Via Aroma",0.6,IF(D20="Dicorpo",0.8,"")))) -> 0.6 | K20: =IF(I20="","",I20*(1+J20)) -> 33.6 | L20: =IF(I20="","",I20*1.3) -> 27.3 | M20: =0.0612 -> 0.0612 | N20: =IF(K20="","",K20/(1-M20)) -> 35.790371 | O20: =0.124 -> 0.124 | P20: =IF(K20="","",K20/(1-O20)) -> 38.356164 | Q20: =SUMIFS(Entradas!D:D,Entradas!B:B,B20,Entradas!C:C,C20) - SUMIFS(Vendas!E:E,Vendas!C:C,B20,Vendas!D:D,C20) -> 0
A21: ="P" & TEXT(ROW(A21),"000") -> P021 | B21: AGUA PERF. VIA AROMA 500ML CLASSICA BABY | D21: Via Aroma | E21: 19.5 | F21: 1.2 | G21: 2.3 | H21: =IF(OR(D21="Perfume",D21="Via Aroma"),5,"") -> 5 | I21: =SUM(E21:H21) -> 28 | J21: =IF(D21="","",IF(D21="Perfume",1,IF(D21="Via Aroma",0.6,IF(D21="Dicorpo",0.8,"")))) -> 0.6 | K21: =IF(I21="","",I21*(1+J21)) -> 44.8 | L21: =IF(I21="","",I21*1.3) -> 36.4 | M21: =0.0612 -> 0.0612 | N21: =IF(K21="","",K21/(1-M21)) -> 47.720494 | O21: =0.124 -> 0.124 | P21: =IF(K21="","",K21/(1-O21)) -> 51.141553 | Q21: =SUMIFS(Entradas!D:D,Entradas!B:B,B21,Entradas!C:C,C21) - SUMIFS(Vendas!E:E,Vendas!C:C,B21,Vendas!D:D,C21) -> 0
A22: ="P" & TEXT(ROW(A22),"000") -> P022 | B22: AGUA PERF. VIA AROMA 500ML CLASSICA BLACK VANILLA | D22: Via Aroma | E22: 19.5 | F22: 1.2 | G22: 2.3 | H22: =IF(OR(D22="Perfume",D22="Via Aroma"),5,"") -> 5 | I22: =SUM(E22:H22) -> 28 | J22: =IF(D22="","",IF(D22="Perfume",1,IF(D22="Via Aroma",0.6,IF(D22="Dicorpo",0.8,"")))) -> 0.6 | K22: =IF(I22="","",I22*(1+J22)) -> 44.8 | L22: =IF(I22="","",I22*1.3) -> 36.4 | M22: =0.0612 -> 0.0612 | N22: =IF(K22="","",K22/(1-M22)) -> 47.720494 | O22: =0.124 -> 0.124 | P22: =IF(K22="","",K22/(1-O22)) -> 51.141553 | Q22: =SUMIFS(Entradas!D:D,Entradas!B:B,B22,Entradas!C:C,C22) - SUMIFS(Vendas!E:E,Vendas!C:C,B22,Vendas!D:D,C22) -> 0
A23: ="P" & TEXT(ROW(A23),"000") -> P023 | B23: AROMAT. VIA AROMA ORIGINAL | D23: Via Aroma | E23: 19 | F23: 1.2 | G23: 2.3 | H23: =IF(OR(D23="Perfume",D23="Via Aroma"),5,"") -> 5 | I23: =SUM(E23:H23) -> 27.5 | J23: =IF(D23="","",IF(D23="Perfume",1,IF(D23="Via Aroma",0.6,IF(D23="Dicorpo",0.8,"")))) -> 0.6 | K23: =IF(I23="","",I23*(1+J23)) -> 44 | L23: =IF(I23="","",I23*1.3) -> 35.75 | M23: =0.0612 -> 0.0612 | N23: =IF(K23="","",K23/(1-M23)) -> 46.868343 | O23: =0.124 -> 0.124 | P23: =IF(K23="","",K23/(1-O23)) -> 50.22831 | Q23: =SUMIFS(Entradas!D:D,Entradas!B:B,B23,Entradas!C:C,C23) - SUMIFS(Vendas!E:E,Vendas!C:C,B23,Vendas!D:D,C23) -> 0
A24: ="P" & TEXT(ROW(A24),"000") -> P024 | B24: AROMAT. VIA AROMA STANDARD | D24: Via Aroma | E24: 15.4 | F24: 1.2 | G24: 2.3 | H24: =IF(OR(D24="Perfume",D24="Via Aroma"),5,"") -> 5 | I24: =SUM(E24:H24) -> 23.9 | J24: =IF(D24="","",IF(D24="Perfume",1,IF(D24="Via Aroma",0.6,IF(D24="Dicorpo",0.8,"")))) -> 0.6 | K24: =IF(I24="","",I24*(1+J24)) -> 38.24 | L24: =IF(I24="","",I24*1.3) -> 31.07 | M24: =0.0612 -> 0.0612 | N24: =IF(K24="","",K24/(1-M24)) -> 40.73285 | O24: =0.124 -> 0.124 | P24: =IF(K24="","",K24/(1-O24)) -> 43.652968 | Q24: =SUMIFS(Entradas!D:D,Entradas!B:B,B24,Entradas!C:C,C24) - SUMIFS(Vendas!E:E,Vendas!C:C,B24,Vendas!D:D,C24) -> 0
A25: ="P" & TEXT(ROW(A25),"000") -> P025 | B25: AROMAT. VIA AROMA STANDARD BLACK | D25: Via Aroma | E25: 19 | F25: 1.2 | G25: 2.3 | H25: =IF(OR(D25="Perfume",D25="Via Aroma"),5,"") -> 5 | I25: =SUM(E25:H25) -> 27.5 | J25: =IF(D25="","",IF(D25="Perfume",1,IF(D25="Via Aroma",0.6,IF(D25="Dicorpo",0.8,"")))) -> 0.6 | K25: =IF(I25="","",I25*(1+J25)) -> 44 | L25: =IF(I25="","",I25*1.3) -> 35.75 | M25: =0.0612 -> 0.0612 | N25: =IF(K25="","",K25/(1-M25)) -> 46.868343 | O25: =0.124 -> 0.124 | P25: =IF(K25="","",K25/(1-O25)) -> 50.22831 | Q25: =SUMIFS(Entradas!D:D,Entradas!B:B,B25,Entradas!C:C,C25) - SUMIFS(Vendas!E:E,Vendas!C:C,B25,Vendas!D:D,C25) -> 0
A26: ="P" & TEXT(ROW(A26),"000") -> P026 | B26: AROMAT. VIA AROMA STANDARD C/BAMBOO | D26: Via Aroma | E26: 22.9 | F26: 1.2 | G26: 2.3 | H26: =IF(OR(D26="Perfume",D26="Via Aroma"),5,"") -> 5 | I26: =SUM(E26:H26) -> 31.4 | J26: =IF(D26="","",IF(D26="Perfume",1,IF(D26="Via Aroma",0.6,IF(D26="Dicorpo",0.8,"")))) -> 0.6 | K26: =IF(I26="","",I26*(1+J26)) -> 50.24 | L26: =IF(I26="","",I26*1.3) -> 40.82 | M26: =0.0612 -> 0.0612 | N26: =IF(K26="","",K26/(1-M26)) -> 53.515126 | O26: =0.124 -> 0.124 | P26: =IF(K26="","",K26/(1-O26)) -> 57.351598 | Q26: =SUMIFS(Entradas!D:D,Entradas!B:B,B26,Entradas!C:C,C26) - SUMIFS(Vendas!E:E,Vendas!C:C,B26,Vendas!D:D,C26) -> 0
A27: ="P" & TEXT(ROW(A27),"000") -> P027 | B27: DIFUSOR VARETAS 200ML BAMBOO | D27: Via Aroma | E27: 35 | F27: 1.2 | G27: 2.3 | H27: =IF(OR(D27="Perfume",D27="Via Aroma"),5,"") -> 5 | I27: =SUM(E27:H27) -> 43.5 | J27: =IF(D27="","",IF(D27="Perfume",1,IF(D27="Via Aroma",0.6,IF(D27="Dicorpo",0.8,"")))) -> 0.6 | K27: =IF(I27="","",I27*(1+J27)) -> 69.6 | L27: =IF(I27="","",I27*1.3) -> 56.55 | M27: =0.0612 -> 0.0612 | N27: =IF(K27="","",K27/(1-M27)) -> 74.137196 | O27: =0.124 -> 0.124 | P27: =IF(K27="","",K27/(1-O27)) -> 79.452055 | Q27: =SUMIFS(Entradas!D:D,Entradas!B:B,B27,Entradas!C:C,C27) - SUMIFS(Vendas!E:E,Vendas!C:C,B27,Vendas!D:D,C27) -> 0
A28: ="P" & TEXT(ROW(A28),"000") -> P028 | B28: DIFUSOR VARETAS 200ML JASMIM BRANCO | D28: Via Aroma | E28: 31.5 | F28: 1.2 | G28: 2.3 | H28: =IF(OR(D28="Perfume",D28="Via Aroma"),5,"") -> 5 | I28: =SUM(E28:H28) -> 40 | J28: =IF(D28="","",IF(D28="Perfume",1,IF(D28="Via Aroma",0.6,IF(D28="Dicorpo",0.8,"")))) -> 0.6 | K28: =IF(I28="","",I28*(1+J28)) -> 64 | L28: =IF(I28="","",I28*1.3) -> 52 | M28: =0.0612 -> 0.0612 | N28: =IF(K28="","",K28/(1-M28)) -> 68.172135 | O28: =0.124 -> 0.124 | P28: =IF(K28="","",K28/(1-O28)) -> 73.059361 | Q28: =SUMIFS(Entradas!D:D,Entradas!B:B,B28,Entradas!C:C,C28) - SUMIFS(Vendas!E:E,Vendas!C:C,B28,Vendas!D:D,C28) -> 0
A29: ="P" & TEXT(ROW(A29),"000") -> P029 | B29: DIFUSOR CASZULO 250ML BAMBU | D29: Via Aroma | E29: 14.5 | F29: 1.2 | G29: 2.3 | H29: =IF(OR(D29="Perfume",D29="Via Aroma"),5,"") -> 5 | I29: =SUM(E29:H29) -> 23 | J29: =IF(D29="","",IF(D29="Perfume",1,IF(D29="Via Aroma",0.6,IF(D29="Dicorpo",0.8,"")))) -> 0.6 | K29: =IF(I29="","",I29*(1+J29)) -> 36.8 | L29: =IF(I29="","",I29*1.3) -> 29.9 | M29: =0.0612 -> 0.0612 | N29: =IF(K29="","",K29/(1-M29)) -> 39.198977 | O29: =0.124 -> 0.124 | P29: =IF(K29="","",K29/(1-O29)) -> 42.009132 | Q29: =SUMIFS(Entradas!D:D,Entradas!B:B,B29,Entradas!C:C,C29) - SUMIFS(Vendas!E:E,Vendas!C:C,B29,Vendas!D:D,C29) -> 0
A30: ="P" & TEXT(ROW(A30),"000") -> P030 | B30: DIFUSOR CASZULO 250ML LAVANDA | D30: Via Aroma | E30: 14.5 | F30: 1.2 | G30: 2.3 | H30: =IF(OR(D30="Perfume",D30="Via Aroma"),5,"") -> 5 | I30: =SUM(E30:H30) -> 23 | J30: =IF(D30="","",IF(D30="Perfume",1,IF(D30="Via Aroma",0.6,IF(D30="Dicorpo",0.8,"")))) -> 0.6 | K30: =IF(I30="","",I30*(1+J30)) -> 36.8 | L30: =IF(I30="","",I30*1.3) -> 29.9 | M30: =0.0612 -> 0.0612 | N30: =IF(K30="","",K30/(1-M30)) -> 39.198977 | O30: =0.124 -> 0.124 | P30: =IF(K30="","",K30/(1-O30)) -> 42.009132 | Q30: =SUMIFS(Entradas!D:D,Entradas!B:B,B30,Entradas!C:C,C30) - SUMIFS(Vendas!E:E,Vendas!C:C,B30,Vendas!D:D,C30) -> 0
... A107: ="P" & TEXT(ROW(A107),"000") -> P107 | B107: SACHE 25G WOOD | D107: Via Aroma | E107: 6.5 | F107: 0.86 | G107: 1.08 | H107: =IF(OR(D107="Perfume",D107="Via Aroma"),5,"") -> 5 | I107: =SUM(E107:H107) -> 13.44 | J107: =IF(D107="","",IF(D107="Perfume",1,IF(D107="Via Aroma",0.6,IF(D107="Dicorpo",0.8,"")))) -> 0.6 | K107: =IF(I107="","",I107*(1+J107)) -> 21.504 | L107: =IF(I107="","",I107*1.3) -> 17.472 | M107: =0.0612 -> 0.0612 | N107: =IF(K107="","",K107/(1-M107)) -> 22.905837 | O107: =0.124 -> 0.124 | P107: =IF(K107="","",K107/(1-O107)) -> 24.547945 | Q107: =SUMIFS(Entradas!D:D,Entradas!B:B,B107,Entradas!C:C,C107) - SUMIFS(Vendas!E:E,Vendas!C:C,B107,Vendas!D:D,C107) -> 0
A108: ="P" & TEXT(ROW(A108),"000") -> P108 | H108: =IF(OR(D108="Perfume",D108="Via Aroma"),5,"") | I108: =SUM(E108:H108) -> 0 | J108: =IF(D108="","",IF(D108="Perfume",1,IF(D108="Via Aroma",0.6,IF(D108="Dicorpo",0.8,"")))) | K108: =IF(I108="","",I108*(1+J108)) -> 0 | L108: =IF(I108="","",I108*1.3) -> 0 | M108: =0.0612 -> 0.0612 | N108: =IF(K108="","",K108/(1-M108)) -> 0 | O108: =0.124 -> 0.124 | P108: =IF(K108="","",K108/(1-O108)) -> 0 | Q108: =SUMIFS(Entradas!D:D,Entradas!B:B,B108,Entradas!C:C,C108) - SUMIFS(Vendas!E:E,Vendas!C:C,B108,Vendas!D:D,C108) -> 0
A109: ="P" & TEXT(ROW(A109),"000") -> P109 | H109: =IF(OR(D109="Perfume",D109="Via Aroma"),5,"") | I109: =SUM(E109:H109) -> 0 | J109: =IF(D109="","",IF(D109="Perfume",1,IF(D109="Via Aroma",0.6,IF(D109="Dicorpo",0.8,"")))) | K109: =IF(I109="","",I109*(1+J109)) -> 0 | L109: =IF(I109="","",I109*1.3) -> 0 | M109: =0.0612 -> 0.0612 | N109: =IF(K109="","",K109/(1-M109)) -> 0 | O109: =0.124 -> 0.124 | P109: =IF(K109="","",K109/(1-O109)) -> 0 | Q109: =SUMIFS(Entradas!D:D,Entradas!B:B,B109,Entradas!C:C,C109) - SUMIFS(Vendas!E:E,Vendas!C:C,B109,Vendas!D:D,C109) -> 0
A110: ="P" & TEXT(ROW(A110),"000") -> P110 | H110: =IF(OR(D110="Perfume",D110="Via Aroma"),5,"") | I110: =SUM(E110:H110) -> 0 | J110: =IF(D110="","",IF(D110="Perfume",1,IF(D110="Via Aroma",0.6,IF(D110="Dicorpo",0.8,"")))) | K110: =IF(I110="","",I110*(1+J110)) -> 0 | L110: =IF(I110="","",I110*1.3) -> 0 | M110: =0.0612 -> 0.0612 | N110: =IF(K110="","",K110/(1-M110)) -> 0 | O110: =0.124 -> 0.124 | P110: =IF(K110="","",K110/(1-O110)) -> 0 | Q110: =SUMIFS(Entradas!D:D,Entradas!B:B,B110,Entradas!C:C,C110) - SUMIFS(Vendas!E:E,Vendas!C:C,B110,Vendas!D:D,C110) -> 0
A111: ="P" & TEXT(ROW(A111),"000") -> P111 | H111: =IF(OR(D111="Perfume",D111="Via Aroma"),5,"") | I111: =SUM(E111:H111) -> 0 | J111: =IF(D111="","",IF(D111="Perfume",1,IF(D111="Via Aroma",0.6,IF(D111="Dicorpo",0.8,"")))) | K111: =IF(I111="","",I111*(1+J111)) -> 0 | L111: =IF(I111="","",I111*1.3) -> 0 | M111: =0.0612 -> 0.0612 | N111: =IF(K111="","",K111/(1-M111)) -> 0 | O111: =0.124 -> 0.124 | P111: =IF(K111="","",K111/(1-O111)) -> 0 | Q111: =SUMIFS(Entradas!D:D,Entradas!B:B,B111,Entradas!C:C,C111) - SUMIFS(Vendas!E:E,Vendas!C:C,B111,Vendas!D:D,C111) -> 0
A112: ="P" & TEXT(ROW(A112),"000") -> P112 | H112: =IF(OR(D112="Perfume",D112="Via Aroma"),5,"") | I112: =SUM(E112:H112) -> 0 | J112: =IF(D112="","",IF(D112="Perfume",1,IF(D112="Via Aroma",0.6,IF(D112="Dicorpo",0.8,"")))) | K112: =IF(I112="","",I112*(1+J112)) -> 0 | L112: =IF(I112="","",I112*1.3) -> 0 | M112: =0.0612 -> 0.0612 | N112: =IF(K112="","",K112/(1-M112)) -> 0 | O112: =0.124 -> 0.124 | P112: =IF(K112="","",K112/(1-O112)) -> 0 | Q112: =SUMIFS(Entradas!D:D,Entradas!B:B,B112,Entradas!C:C,C112) - SUMIFS(Vendas!E:E,Vendas!C:C,B112,Vendas!D:D,C112) -> 0
A113: ="P" & TEXT(ROW(A113),"000") -> P113 | H113: =IF(OR(D113="Perfume",D113="Via Aroma"),5,"") | I113: =SUM(E113:H113) -> 0 | J113: =IF(D113="","",IF(D113="Perfume",1,IF(D113="Via Aroma",0.6,IF(D113="Dicorpo",0.8,"")))) | K113: =IF(I113="","",I113*(1+J113)) -> 0 | L113: =IF(I113="","",I113*1.3) -> 0 | M113: =0.0612 -> 0.0612 | N113: =IF(K113="","",K113/(1-M113)) -> 0 | O113: =0.124 -> 0.124 | P113: =IF(K113="","",K113/(1-O113)) -> 0 | Q113: =SUMIFS(Entradas!D:D,Entradas!B:B,B113,Entradas!C:C,C113) - SUMIFS(Vendas!E:E,Vendas!C:C,B113,Vendas!D:D,C113) -> 0
A114: ="P" & TEXT(ROW(A114),"000") -> P114 | H114: =IF(OR(D114="Perfume",D114="Via Aroma"),5,"") | I114: =SUM(E114:H114) -> 0 | J114: =IF(D114="","",IF(D114="Perfume",1,IF(D114="Via Aroma",0.6,IF(D114="Dicorpo",0.8,"")))) | K114: =IF(I114="","",I114*(1+J114)) -> 0 | L114: =IF(I114="","",I114*1.3) -> 0 | M114: =0.0612 -> 0.0612 | N114: =IF(K114="","",K114/(1-M114)) -> 0 | O114: =0.124 -> 0.124 | P114: =IF(K114="","",K114/(1-O114)) -> 0 | Q114: =SUMIFS(Entradas!D:D,Entradas!B:B,B114,Entradas!C:C,C114) - SUMIFS(Vendas!E:E,Vendas!C:C,B114,Vendas!D:D,C114) -> 0
A115: ="P" & TEXT(ROW(A115),"000") -> P115 | H115: =IF(OR(D115="Perfume",D115="Via Aroma"),5,"") | I115: =SUM(E115:H115) -> 0 | J115: =IF(D115="","",IF(D115="Perfume",1,IF(D115="Via Aroma",0.6,IF(D115="Dicorpo",0.8,"")))) | K115: =IF(I115="","",I115*(1+J115)) -> 0 | L115: =IF(I115="","",I115*1.3) -> 0 | M115: =0.0612 -> 0.0612 | N115: =IF(K115="","",K115/(1-M115)) -> 0 | O115: =0.124 -> 0.124 | P115: =IF(K115="","",K115/(1-O115)) -> 0 | Q115: =SUMIFS(Entradas!D:D,Entradas!B:B,B115,Entradas!C:C,C115) - SUMIFS(Vendas!E:E,Vendas!C:C,B115,Vendas!D:D,C115) -> 0
A116: ="P" & TEXT(ROW(A116),"000") -> P116 | H116: =IF(OR(D116="Perfume",D116="Via Aroma"),5,"") | I116: =SUM(E116:H116) -> 0 | J116: =IF(D116="","",IF(D116="Perfume",1,IF(D116="Via Aroma",0.6,IF(D116="Dicorpo",0.8,"")))) | K116: =IF(I116="","",I116*(1+J116)) -> 0 | L116: =IF(I116="","",I116*1.3) -> 0 | M116: =0.0612 -> 0.0612 | N116: =IF(K116="","",K116/(1-M116)) -> 0 | O116: =0.124 -> 0.124 | P116: =IF(K116="","",K116/(1-O116)) -> 0 | Q116: =SUMIFS(Entradas!D:D,Entradas!B:B,B116,Entradas!C:C,C116) - SUMIFS(Vendas!E:E,Vendas!C:C,B116,Vendas!D:D,C116) -> 0
...

Sheet Resumo
A1: Faturamento | B1: =SUM(Vendas!G:G) -> 2478.86 | E1: Forma | H1: Total Entradas | I1: Total Saídas | J1: Saldo Atual
A2: Lucro | B2: =SUM(Vendas!I:I) -> 279.11 | E2: Pix | H2: =SUMIF(B:B,"Entrada",E:E) -> 0 | I2: =SUMIF(B:B,"Saída",E:E) -> 0 | J2: =SUMIF(B:B,"Entrada",E:E)-SUMIF(B:B,"Saída",E:E) -> 0
A3: Vendas | B3: =COUNTA(Vendas!A:A)-1 -> 1 | E3: Dinheiro
A4: Ticket Médio | B4: =IF(B3=0,"",B1/B3) -> 2478.86 | E4: Cartão 1x
E5: Cartão 3x
A6: Status | B6: Valor | E6: Cartão 12x
A7: Pago | B7: =SUMIF(Vendas!K:K,"Pago",Vendas!G:G) -> 0
A8: Pendente | B8: =SUMIF(Vendas!K:K,"Pendente",Vendas!G:G) -> 2478.86
A10: PRODUTO MAIS VENDIDO
A11: {=INDEX(Vendas!C2:C1001,MATCH(MAX(COUNTIF(Vendas!C2:C1001,Vendas!C2:C1001)),COUNTIF(Vendas!C2:C1001,Vendas!C2:C1001),0))} -> 02167 - Legging Preto
A13: mês atual
A14: =IFERROR(SUMPRODUCT((MONTH(Vendas!A2:A1001)=MONTH(TODAY()))*(YEAR(Vendas!A2:A1001)=YEAR(TODAY()))*(Vendas!G2:G1001)),0) -> 125

Sheet Entradas
A1: Data | B1: Produto | C1: Tamanho | D1: Quantidade | E1: Custo | F1: Total | Z1: Entradas
B2: 1398 - Cachecol Preto | C2: U | D2: 1 | E2: {=IF(B2="","",IFERROR(INDEX(Produtos!E:E,MATCH(B2&C2,Produtos!B:B&Produtos!C:C,0)),""))} -> 43.46 | F2: =IF(D2="","",D2*E2) -> 43.46 | Z2: =IFERROR(__xludf.DUMMYFUNCTION("FILTER(Config!E:E,TRIM(Config!D:D)=TRIM(B2))"),"#N/A") -> #N/A
B3: 02131-I - Legging Básica Seamless Khaki | C3: G | D3: 1 | E3: {=IF(B3="","",IFERROR(INDEX(Produtos!E:E,MATCH(B3&C3,Produtos!B:B&Produtos!C:C,0)),""))} -> 86.93 | F3: =IF(D3="","",D3*E3) -> 86.93
B4: 02167 - Legging Preto | C4: M | D4: 2 | E4: {=IF(B4="","",IFERROR(INDEX(Produtos!E:E,MATCH(B4&C4,Produtos!B:B&Produtos!C:C,0)),""))} -> 109.62 | F4: =IF(D4="","",D4*E4) -> 219.24
B5: 02167 - Legging Preto | C5: G | D5: 2 | E5: {=IF(B5="","",IFERROR(INDEX(Produtos!E:E,MATCH(B5&C5,Produtos!B:B&Produtos!C:C,0)),""))} -> 109.62 | F5: =IF(D5="","",D5*E5) -> 219.24
B6: 02167 - Legging Preto | C6: GG | D6: 1 | E6: {=IF(B6="","",IFERROR(INDEX(Produtos!E:E,MATCH(B6&C6,Produtos!B:B&Produtos!C:C,0)),""))} -> 109.62 | F6: =IF(D6="","",D6*E6) -> 109.62
B7: 02167 - Legging VD Safari | C7: M | D7: 1 | E7: {=IF(B7="","",IFERROR(INDEX(Produtos!E:E,MATCH(B7&C7,Produtos!B:B&Produtos!C:C,0)),""))} -> 109.62 | F7: =IF(D7="","",D7*E7) -> 109.62
B8: 02167 - Legging VD Safari | C8: GG | D8: 1 | E8: {=IF(B8="","",IFERROR(INDEX(Produtos!E:E,MATCH(B8&C8,Produtos!B:B&Produtos!C:C,0)),""))} -> 109.62 | F8: =IF(D8="","",D8*E8) -> 109.62
B9: 02169 - Pescador Preto | C9: M | D9: 1 | E9: {=IF(B9="","",IFERROR(INDEX(Produtos!E:E,MATCH(B9&C9,Produtos!B:B&Produtos!C:C,0)),""))} -> 93.23 | F9: =IF(D9="","",D9*E9) -> 93.23
B10: 12735 - Camiseta Branco | C10: GG | D10: 1 | E10: {=IF(B10="","",IFERROR(INDEX(Produtos!E:E,MATCH(B10&C10,Produtos!B:B&Produtos!C:C,0)),""))} -> 95.76 | F10: =IF(D10="","",D10*E10) -> 95.76
B11: 12740 - Camiseta Preto | C11: G | D11: 1 | E11: {=IF(B11="","",IFERROR(INDEX(Produtos!E:E,MATCH(B11&C11,Produtos!B:B&Produtos!C:C,0)),""))} -> 87.56 | F11: =IF(D11="","",D11*E11) -> 87.56
B12: 20231 - Conjunto Preto / VD Líquen | C12: M | D12: 1 | E12: {=IF(B12="","",IFERROR(INDEX(Produtos!E:E,MATCH(B12&C12,Produtos!B:B&Produtos!C:C,0)),""))} -> 156.87 | F12: =IF(D12="","",D12*E12) -> 156.87
B13: 20231 - Conjunto AZ Eclipse / AZ Pavão | C13: GG | D13: 1 | E13: {=IF(B13="","",IFERROR(INDEX(Produtos!E:E,MATCH(B13&C13,Produtos!B:B&Produtos!C:C,0)),""))} -> 156.87 | F13: =IF(D13="","",D13*E13) -> 156.87
B14: 20231 - Conjunto AZ Eclipse / AZ Pavão | C14: G | D14: 1 | E14: {=IF(B14="","",IFERROR(INDEX(Produtos!E:E,MATCH(B14&C14,Produtos!B:B&Produtos!C:C,0)),""))} -> 156.87 | F14: =IF(D14="","",D14*E14) -> 156.87
... B18: 15460 - Jaqueta Preto | C18: P | D18: 1 | E18: {=IF(B18="","",IFERROR(INDEX(Produtos!E:E,MATCH(B18&C18,Produtos!B:B&Produtos!C:C,0)),""))} -> 322 | F18: =IF(D18="","",D18*E18) -> 322
B19: AGUA PERF. CASZULO 500ML BAMBU ORIENTAL | D19: 1 | E19: {=IF(B19="","",IFERROR(INDEX(Produtos!E:E,MATCH(B19&C19,Produtos!B:B&Produtos!C:C,0)),""))} -> 12.5 | F19: =IF(D19="","",D19*E19) -> 12.5
B20: AGUA PERF. CASZULO 500ML CAPIM LIMAO | D20: 1 | E20: {=IF(B20="","",IFERROR(INDEX(Produtos!E:E,MATCH(B20&C20,Produtos!B:B&Produtos!C:C,0)),""))} -> 12.5 | F20: =IF(D20="","",D20*E20) -> 12.5
B21: AGUA PERF. VIA AROMA 500ML CLASSICA BABY | D21: 1 | E21: {=IF(B21="","",IFERROR(INDEX(Produtos!E:E,MATCH(B21&C21,Produtos!B:B&Produtos!C:C,0)),""))} -> 19.5 | F21: =IF(D21="","",D21*E21) -> 19.5
B22: AGUA PERF. VIA AROMA 500ML CLASSICA BLACK VANILLA | D22: 1 | E22: {=IF(B22="","",IFERROR(INDEX(Produtos!E:E,MATCH(B22&C22,Produtos!B:B&Produtos!C:C,0)),""))} -> 19.5 | F22: =IF(D22="","",D22*E22) -> 19.5
B23: AROMAT. VIA AROMA ORIGINAL | D23: 1 | E23: {=IF(B23="","",IFERROR(INDEX(Produtos!E:E,MATCH(B23&C23,Produtos!B:B&Produtos!C:C,0)),""))} -> 19 | F23: =IF(D23="","",D23*E23) -> 19
B24: AROMAT. VIA AROMA STANDARD | D24: 1 | E24: {=IF(B24="","",IFERROR(INDEX(Produtos!E:E,MATCH(B24&C24,Produtos!B:B&Produtos!C:C,0)),""))} -> 15.4 | F24: =IF(D24="","",D24*E24) -> 15.4
B25: AROMAT. VIA AROMA STANDARD BLACK | D25: 1 | E25: {=IF(B25="","",IFERROR(INDEX(Produtos!E:E,MATCH(B25&C25,Produtos!B:B&Produtos!C:C,0)),""))} -> 19 | F25: =IF(D25="","",D25*E25) -> 19
B26: AROMAT. VIA AROMA STANDARD C/BAMBOO | D26: 1 | E26: {=IF(B26="","",IFERROR(INDEX(Produtos!E:E,MATCH(B26&C26,Produtos!B:B&Produtos!C:C,0)),""))} -> 22.9 | F26: =IF(D26="","",D26*E26) -> 22.9
B27: DIFUSOR VARETAS 200ML BAMBOO | D27: 1 | E27: {=IF(B27="","",IFERROR(INDEX(Produtos!E:E,MATCH(B27&C27,Produtos!B:B&Produtos!C:C,0)),""))} -> 35 | F27: =IF(D27="","",D27*E27) -> 35
B28: DIFUSOR VARETAS 200ML JASMIM BRANCO | D28: 1 | E28: {=IF(B28="","",IFERROR(INDEX(Produtos!E:E,MATCH(B28&C28,Produtos!B:B&Produtos!C:C,0)),""))} -> 31.5 | F28: =IF(D28="","",D28*E28) -> 31.5
B29: DIFUSOR CASZULO 250ML BAMBU | D29: 1 | E29: {=IF(B29="","",IFERROR(INDEX(Produtos!E:E,MATCH(B29&C29,Produtos!B:B&Produtos!C:C,0)),""))} -> 14.5 | F29: =IF(D29="","",D29*E29) -> 14.5
B30: DIFUSOR CASZULO 250ML LAVANDA | D30: 1 | E30: {=IF(B30="","",IFERROR(INDEX(Produtos!E:E,MATCH(B30&C30,Produtos!B:B&Produtos!C:C,0)),""))} -> 14.5 | F30: =IF(D30="","",D30*E30) -> 14.5
... B107: SACHE 25G WOOD | D107: 1 | E107: {=IF(B107="","",IFERROR(INDEX(Produtos!E:E,MATCH(B107&C107,Produtos!B:B&Produtos!C:C,0)),""))} -> 6.5 | F107: =IF(D107="","",D107*E107) -> 6.5
E108: {=IF(B108="","",IFERROR(INDEX(Produtos!E:E,MATCH(B108&C108,Produtos!B:B&Produtos!C:C,0)),""))} | F108: =IF(D108="","",D108*E108)
E109: {=IF(B109="","",IFERROR(INDEX(Produtos!E:E,MATCH(B109&C109,Produtos!B:B&Produtos!C:C,0)),""))} | F109: =IF(D109="","",D109*E109)
E110: {=IF(B110="","",IFERROR(INDEX(Produtos!E:E,MATCH(B110&C110,Produtos!B:B&Produtos!C:C,0)),""))} | F110: =IF(D110="","",D110*E110)
E111: {=IF(B111="","",IFERROR(INDEX(Produtos!E:E,MATCH(B111&C111,Produtos!B:B&Produtos!C:C,0)),""))} | F111: =IF(D111="","",D111*E111)
E112: {=IF(B112="","",IFERROR(INDEX(Produtos!E:E,MATCH(B112&C112,Produtos!B:B&Produtos!C:C,0)),""))} | F112: =IF(D112="","",D112*E112)
E113: {=IF(B113="","",IFERROR(INDEX(Produtos!E:E,MATCH(B113&C113,Produtos!B:B&Produtos!C:C,0)),""))} | F113: =IF(D113="","",D113*E113)
E114: {=IF(B114="","",IFERROR(INDEX(Produtos!E:E,MATCH(B114&C114,Produtos!B:B&Produtos!C:C,0)),""))} | F114: =IF(D114="","",D114*E114)
E115: {=IF(B115="","",IFERROR(INDEX(Produtos!E:E,MATCH(B115&C115,Produtos!B:B&Produtos!C:C,0)),""))} | F115: =IF(D115="","",D115*E115)
E116: {=IF(B116="","",IFERROR(INDEX(Produtos!E:E,MATCH(B116&C116,Produtos!B:B&Produtos!C:C,0)),""))} | F116: =IF(D116="","",D116*E116)
E117: {=IF(B117="","",IFERROR(INDEX(Produtos!E:E,MATCH(B117&C117,Produtos!B:B&Produtos!C:C,0)),""))} | F117: =IF(D117="","",D117*E117)
E118: {=IF(B118="","",IFERROR(INDEX(Produtos!E:E,MATCH(B118&C118,Produtos!B:B&Produtos!C:C,0)),""))} | F118: =IF(D118="","",D118*E118)
E119: {=IF(B119="","",IFERROR(INDEX(Produtos!E:E,MATCH(B119&C119,Produtos!B:B&Produtos!C:C,0)),""))} | F119: =IF(D119="","",D119*E119)
...

Sheet Financeiro
A1: MES | B1: abril | C1: Ano
A3: Data | B3: Tipo | C3: Categoria | D3: Descrição | E3: Valor | F3: Forma de Pagamento | G3: Status
A4: 46140 | B4: Saída | C4: Fornecedor | D4: Via aroma | E4: 332.64
A5: 46132 | B5: Saída | D5: Das | E5: 82.05

Sheet Financeiro2
B1: Silvana
A4: Data | B4: produto

Sheet Config
A1: Forma de pagamento | B1: Status | D1: Tamanho | G1: Entrada | H1: Venda | J1: fornecedores | L1: Mes
A2: Pix | B2: Pago | D2: PP | G2: Saída | H2: Fornecedor | J2: Di Corpo | L2: janeiro
A3: Dinheiro | B3: Pendente | D3: P | H3: Embalagem | J3: Via Aroma | L3: fevereiro
A4: Boleto | D4: M | H4: Marketing | J4: Perfumes | L4: março
A5: Cartão 1x | D5: G | H5: Transporte | L5: abril
A6: Cartão 3x | D6: GG | H6: Aluguel | L6: maio
A7: Cartão 12x | D7: XGG | H7: Internet | L7: junho
D8: U | H8: Retirada | L8: julho
L9: agosto
L10: setembro
L11: outubro
L12: novembro
L13: dezembro
